[2024-09-11T06:29:24.729+0000] {local_task_job_runner.py:120} INFO - ::group::Pre task execution logs
[2024-09-11T06:29:24.762+0000] {taskinstance.py:2076} INFO - Dependencies all met for dep_context=non-requeueable deps ti=<TaskInstance: dag_ml_pipeline_docker_operator_v03.docker_model_train_and_publish_task_v01 manual__2024-09-11T06:29:22.878799+00:00 [queued]>
[2024-09-11T06:29:24.770+0000] {taskinstance.py:2076} INFO - Dependencies all met for dep_context=requeueable deps ti=<TaskInstance: dag_ml_pipeline_docker_operator_v03.docker_model_train_and_publish_task_v01 manual__2024-09-11T06:29:22.878799+00:00 [queued]>
[2024-09-11T06:29:24.771+0000] {taskinstance.py:2306} INFO - Starting attempt 1 of 1
[2024-09-11T06:29:24.787+0000] {taskinstance.py:2330} INFO - Executing <Task(DockerOperator): docker_model_train_and_publish_task_v01> on 2024-09-11 06:29:22.878799+00:00
[2024-09-11T06:29:24.794+0000] {standard_task_runner.py:90} INFO - Running: ['***', 'tasks', 'run', 'dag_ml_pipeline_docker_operator_v03', 'docker_model_train_and_publish_task_v01', 'manual__2024-09-11T06:29:22.878799+00:00', '--job-id', '8', '--raw', '--subdir', 'DAGS_FOLDER/18_ml_pipeline_with_docker_operator.py', '--cfg-path', '/tmp/tmpjuunrgq5']
[2024-09-11T06:29:24.796+0000] {standard_task_runner.py:91} INFO - Job 8: Subtask docker_model_train_and_publish_task_v01
[2024-09-11T06:29:24.797+0000] {logging_mixin.py:188} WARNING - /home/***/.local/lib/python3.12/site-packages/***/task/task_runner/standard_task_runner.py:61 DeprecationWarning: This process (pid=749) is multi-threaded, use of fork() may lead to deadlocks in the child.
[2024-09-11T06:29:24.798+0000] {standard_task_runner.py:63} INFO - Started process 750 to run task
[2024-09-11T06:29:24.836+0000] {task_command.py:426} INFO - Running <TaskInstance: dag_ml_pipeline_docker_operator_v03.docker_model_train_and_publish_task_v01 manual__2024-09-11T06:29:22.878799+00:00 [running]> on host b7a43554df14
[2024-09-11T06:29:24.912+0000] {taskinstance.py:2648} INFO - Exporting env vars: AIRFLOW_CTX_DAG_OWNER='coder2j' AIRFLOW_CTX_DAG_ID='dag_ml_pipeline_docker_operator_v03' AIRFLOW_CTX_TASK_ID='docker_model_train_and_publish_task_v01' AIRFLOW_CTX_EXECUTION_DATE='2024-09-11T06:29:22.878799+00:00' AIRFLOW_CTX_TRY_NUMBER='1' AIRFLOW_CTX_DAG_RUN_ID='manual__2024-09-11T06:29:22.878799+00:00'
[2024-09-11T06:29:24.913+0000] {taskinstance.py:430} INFO - ::endgroup::
[2024-09-11T06:29:26.794+0000] {docker.py:157} ERROR - Failed to establish connection to Docker host tcp://docker-socket-proxy:2375: Error while fetching server API version: HTTPConnectionPool(host='docker-socket-proxy', port=2375): Max retries exceeded with url: /version (Caused by NameResolutionError("<urllib3.connection.HTTPConnection object at 0x7fec23351880>: Failed to resolve 'docker-socket-proxy' ([Errno -2] Name or service not known)"))
[2024-09-11T06:29:26.795+0000] {taskinstance.py:441} INFO - ::group::Post task execution logs
[2024-09-11T06:29:26.803+0000] {taskinstance.py:2905} ERROR - Task failed with exception
Traceback (most recent call last):
  File "/home/airflow/.local/lib/python3.12/site-packages/airflow/models/taskinstance.py", line 465, in _execute_task
    result = _execute_callable(context=context, **execute_callable_kwargs)
             ^^^^^^^^^^^^^^^^^^^^^^^^^^^^^^^^^^^^^^^^^^^^^^^^^^^^^^^^^^^^^
  File "/home/airflow/.local/lib/python3.12/site-packages/airflow/models/taskinstance.py", line 432, in _execute_callable
    return execute_callable(context=context, **execute_callable_kwargs)
           ^^^^^^^^^^^^^^^^^^^^^^^^^^^^^^^^^^^^^^^^^^^^^^^^^^^^^^^^^^^^
  File "/home/airflow/.local/lib/python3.12/site-packages/airflow/models/baseoperator.py", line 401, in wrapper
    return func(self, *args, **kwargs)
           ^^^^^^^^^^^^^^^^^^^^^^^^^^^
  File "/home/airflow/.local/lib/python3.12/site-packages/airflow/providers/docker/operators/docker.py", line 492, in execute
    if self.force_pull or not self.cli.images(name=self.image):
                              ^^^^^^^^
  File "/home/airflow/.local/lib/python3.12/site-packages/airflow/providers/docker/operators/docker.py", line 362, in cli
    return self.hook.api_client
           ^^^^^^^^^^^^^^^^^^^^
  File "/usr/local/lib/python3.12/functools.py", line 995, in __get__
    val = self.func(instance)
          ^^^^^^^^^^^^^^^^^^^
  File "/home/airflow/.local/lib/python3.12/site-packages/airflow/providers/docker/hooks/docker.py", line 161, in api_client
    raise AirflowException("Failed to establish connection to any given Docker hosts.")
airflow.exceptions.AirflowException: Failed to establish connection to any given Docker hosts.
[2024-09-11T06:29:26.807+0000] {taskinstance.py:1206} INFO - Marking task as FAILED. dag_id=dag_ml_pipeline_docker_operator_v03, task_id=docker_model_train_and_publish_task_v01, run_id=manual__2024-09-11T06:29:22.878799+00:00, execution_date=20240911T062922, start_date=20240911T062924, end_date=20240911T062926
[2024-09-11T06:29:26.823+0000] {standard_task_runner.py:110} ERROR - Failed to execute job 8 for task docker_model_train_and_publish_task_v01 (Failed to establish connection to any given Docker hosts.; 750)
[2024-09-11T06:29:26.858+0000] {local_task_job_runner.py:240} INFO - Task exited with return code 1
[2024-09-11T06:29:26.872+0000] {taskinstance.py:3503} INFO - 0 downstream tasks scheduled from follow-on schedule check
[2024-09-11T06:29:26.877+0000] {local_task_job_runner.py:222} INFO - ::endgroup::
